<?xml version="1.0"?>
<robot name="my_first_robot_arm">


<link name="base_link">
    <visual>
        <origin rpy="0 0 0" xyz="0 0 0" />
        <geometry>
            <cylinder length="0.1" radius="0.2" />
        </geometry>
        <material name="green">
            <color rgba="0.2 1.0 0.2 1.0"/>
        </material>
    </visual>
<collision>
    <origin rpy="0 0 0" xyz="0 0 0" />
    <geometry>
        <cylinder length="0.1" radius="0.2" />
    </geometry>
    <material name="green">
        <color rgba="0.2 1.0 0.2 1.0"/>
    </material>
</collision>
<inertial>
<origin xyz="0 0 0" rpy="0 0 0"/>
<mass value="4" />
<inertia ixx="1.0" ixy="0.0" ixz="0.0" iyy="1.0" iyz="0.0" izz="1.0" />
</inertial>
</link>

<!-- joint 2 -->
<joint name="joint_base_link_to_link_1" type="revolute">
<parent link="base_link" />
<child link="link_1" />
<origin xyz="0 0 0.05" rpy="0 0 0" />
<axis xyz="0 0 1" />
<limit lower="-1.57" upper="1.57" effort="0" velocity="0.5" />
</joint>

<link name="link_1">
<visual>
<origin xyz="0 0 0" rpy="0 0 0"/>
<geometry>
<mesh filename="package://my_robot_description/meshes/arm_link.stl" scale="1 1 1" />
</geometry>
<material name="red">
<color rgba="0.8 0.0 0.0 1.0"/>
</material>
</visual>
<collision>
<origin xyz="0 0 0" rpy="0 0 0"/>
<geometry>
<mesh filename="package://my_robot_description/meshes/arm_link.stl" scale="1 1 1"/>
</geometry>
<material name="red">
<color rgba="0.8 0.0 0.0 1.0"/>
</material>
</collision>
<inertial>
<origin xyz="0 0 0" rpy="0 0 0"/>
<mass value="1" />
<inertia ixx="1.0" ixy="0.0" ixz="0.0" iyy="1.0" iyz="0.0" izz="1.0" />
</inertial>
</link>

<!-- joint 2 -->
<joint name="joint_link_2_to_link_1" type="revolute">
<parent link="link_1" />
<child link="link_2" />
<origin xyz="0.5 0.0 0.0" rpy="0.0 0 0.0" />
<axis xyz="0 0 1" />
<limit lower="-1.57" upper="1.57" effort="0" velocity="0.5" />
</joint>

<link name="link_2">
<visual>
<geometry>
<mesh filename="package://my_robot_description/meshes/arm_link.stl" scale="1 1 1" />
</geometry>
<material name="red"/>
</visual>
<collision>
<geometry>
<mesh filename="package://my_robot_description/meshes/arm_link.stl" scale="1 1 1" />
</geometry>
<material name="red"/>
</collision>
<inertial>
<origin xyz="0 0 0.25" rpy="0 0 0" />
<mass value="1" />
<inertia ixx="1.0" ixy="0.0" ixz="0.0" iyy="1.0" iyz="0.0" izz="1.0" />
</inertial>
</link>

<joint name="joint_link_2_to_gripper" type="revolute">
<parent link="link_2" />
<child link="gripper" />
<origin xyz="0.5 0.0 0.0" rpy="0.0 0 0.0" />
<axis xyz="0 0 1" />
<limit lower="-1.57" upper="1.57" effort="0" velocity="0.5" />
</joint>

<link name="gripper">
<visual>
<geometry>
<mesh filename="package://my_robot_description/meshes/gripper.stl" scale="1 1 1" />
</geometry>
<material name="cayn">
<color rgba="0 1.0 1.0 1.0" />
</material>
</visual>
<collision>
<geometry>
<mesh filename="package://my_robot_description/meshes/gripper.stl" scale="1 1 1" />
</geometry>
<material name="grey">
<color rgba="0 1.0 1.0 1.0" />
</material>
</collision>
<inertial>
<origin xyz="0 0 0.1" rpy="0 0 0" />
<mass value="1" />
<inertia ixx="1.0" ixy="0.0" ixz="0.0" iyy="1.0" iyz="0.0" izz="1.0" />
</inertial>
</link>

<joint name="joint_gripper_to_tip" type="fixed">
<parent link="gripper" />
<child link="tip" />
<origin xyz="0.18 0.0 0" rpy="0 0 0"/>
</joint>

<link name="tip" />

</robot>